<sdf version='1.10'>
  <world name='Moving_robot'>
    <physics name='1ms' type='ignored'>
      <max_step_size>0.001</max_step_size>
      <real_time_factor>1</real_time_factor>
      <real_time_update_rate>1000</real_time_update_rate>
    </physics>
    <plugin name='gz::sim::systems::Physics' filename='gz-sim-physics-system'/>
    <plugin name='gz::sim::systems::UserCommands' filename='gz-sim-user-commands-system'/>
    <plugin name='gz::sim::systems::SceneBroadcaster' filename='gz-sim-scene-broadcaster-system'/>
    <plugin name='gz::sim::systems::Sensors' filename='gz-sim-sensors-system'>
      <render_engine>ogre2</render_engine>
    </plugin>
    <actor name='actor_walking'>
      <skin>
        <filename>https://fuel.gazebosim.org/1.0/Mingfei/models/actor/tip/files/meshes/walk.dae</filename>
        <scale>1</scale>
      </skin>
      <animation name='walk'>
        <filename>https://fuel.gazebosim.org/1.0/Mingfei/models/actor/tip/files/meshes/walk.dae</filename>
      </animation>
      <script>
        <loop>true</loop>
        <delay_start>0</delay_start>
        <auto_start>true</auto_start>
        <trajectory id='0' type='walk'>
          <waypoint>
            <time>0</time>
            <pose>0 -16 1 0 0 1.5700000000000001</pose>
          </waypoint>
          <waypoint>
            <time>3</time>
            <pose>0 -2 1 0 0 1.5700000000000001</pose>
          </waypoint>
          <waypoint>
            <time>4</time>
            <pose>0 -2 1 0 0 1.5700000000000001</pose>
          </waypoint>
          <waypoint>
            <time>4.5</time>
            <pose>0 -2 1 0 0 -1.5700000000000001</pose>
          </waypoint>
          <waypoint>
            <time>7.5</time>
            <pose>0 -16 1 0 0 -1.5700000000000001</pose>
          </waypoint>
          <waypoint>
            <time>8.5</time>
            <pose>0 -16 1 0 0 -1.5700000000000001</pose>
          </waypoint>
          <waypoint>
            <time>9</time>
            <pose>0 -16 1 0 0 1.5700000000000001</pose>
          </waypoint>
        </trajectory>
      </script>
    </actor>
    <gravity>0 0 -9.8000000000000007</gravity>
    <magnetic_field>5.5644999999999998e-06 2.2875799999999999e-05 -4.2388400000000002e-05</magnetic_field>
    <atmosphere type='adiabatic'/>
    <scene>
      <ambient>0.400000006 0.400000006 0.400000006 1</ambient>
      <background>0.699999988 0.699999988 0.699999988 1</background>
      <shadows>true</shadows>
    </scene>
    <model name='MaleVisitorOnPhone'>
      <static>true</static>
      <link name='body'>
        <pose>0 0 0 0 0 0</pose>
        <visual name='visual'>
          <geometry>
            <mesh>
              <uri>https://fuel.gazebosim.org/1.0/openrobotics/models/malevisitoronphone/2/files/meshes/MaleVisitorStatic.obj</uri>
            </mesh>
          </geometry>
        </visual>
        <collision name='collision'>
          <geometry>
            <mesh>
              <uri>https://fuel.gazebosim.org/1.0/openrobotics/models/malevisitoronphone/2/files/meshes/MaleVisitorStatic_Col.obj</uri>
            </mesh>
          </geometry>
        </collision>
        <inertial>
          <pose>0 0 0 0 0 0</pose>
          <mass>1</mass>
          <inertia>
            <ixx>1</ixx>
            <ixy>0</ixy>
            <ixz>0</ixz>
            <iyy>1</iyy>
            <iyz>0</iyz>
            <izz>1</izz>
          </inertia>
        </inertial>
        <enable_wind>false</enable_wind>
      </link>
      <pose>1.219480037689209 -10.897405624389648 0 0 0 0</pose>
      <self_collide>false</self_collide>
    </model>
    <model name='Oak tree'>
      <static>true</static>
      <link name='link'>
        <collision name='collision'>
          <geometry>
            <mesh>
              <uri>https://fuel.gazebosim.org/1.0/openrobotics/models/oak tree/7/files/meshes/oak_tree.dae</uri>
            </mesh>
          </geometry>
        </collision>
        <visual name='branch'>
          <geometry>
            <mesh>
              <uri>https://fuel.gazebosim.org/1.0/openrobotics/models/oak tree/7/files/meshes/oak_tree.dae</uri>
              <submesh>
                <name>Branch</name>
              </submesh>
            </mesh>
          </geometry>
          <material>
            <double_sided>true</double_sided>
            <diffuse>1 1 1 1</diffuse>
            <script>
              <uri>https://fuel.gazebosim.org/1.0/openrobotics/models/oak tree/7/files/materials/scripts/</uri>
              <uri>https://fuel.gazebosim.org/1.0/openrobotics/models/oak tree/7/files/materials/textures/</uri>
              <name>OakTree/Branch</name>
            </script>
            <pbr>
              <metal>
                <albedo_map>https://fuel.gazebosim.org/1.0/openrobotics/models/oak tree/7/files/materials/textures/branch_diffuse.png</albedo_map>
              </metal>
            </pbr>
          </material>
        </visual>
        <visual name='bark'>
          <geometry>
            <mesh>
              <uri>https://fuel.gazebosim.org/1.0/openrobotics/models/oak tree/7/files/meshes/oak_tree.dae</uri>
              <submesh>
                <name>Bark</name>
              </submesh>
            </mesh>
          </geometry>
          <material>
            <diffuse>1 1 1 1</diffuse>
            <script>
              <uri>https://fuel.gazebosim.org/1.0/openrobotics/models/oak tree/7/files/materials/scripts/</uri>
              <uri>https://fuel.gazebosim.org/1.0/openrobotics/models/oak tree/7/files/materials/textures/</uri>
              <name>OakTree/Bark</name>
            </script>
            <pbr>
              <metal>
                <albedo_map>https://fuel.gazebosim.org/1.0/openrobotics/models/oak tree/7/files/materials/textures/bark_diffuse.png</albedo_map>
              </metal>
            </pbr>
          </material>
        </visual>
        <pose>0 0 0 0 0 0</pose>
        <inertial>
          <pose>0 0 0 0 0 0</pose>
          <mass>1</mass>
          <inertia>
            <ixx>1</ixx>
            <ixy>0</ixy>
            <ixz>0</ixz>
            <iyy>1</iyy>
            <iyz>0</iyz>
            <izz>1</izz>
          </inertia>
        </inertial>
        <enable_wind>false</enable_wind>
      </link>
      <pose>16.249599456787109 -10.326713562011719 0 0 0 0</pose>
      <self_collide>false</self_collide>
    </model>
    <model name='Pine Tree'>
      <static>true</static>
      <link name='link'>
        <collision name='collision'>
          <geometry>
            <mesh>
              <uri>https://fuel.gazebosim.org/1.0/openrobotics/models/pine tree/6/files/meshes/pine_tree.dae</uri>
            </mesh>
          </geometry>
        </collision>
        <visual name='branch'>
          <geometry>
            <mesh>
              <uri>https://fuel.gazebosim.org/1.0/openrobotics/models/pine tree/6/files/meshes/pine_tree.dae</uri>
              <submesh>
                <name>Branch</name>
              </submesh>
            </mesh>
          </geometry>
          <material>
            <double_sided>true</double_sided>
            <diffuse>1 1 1 1</diffuse>
            <script>
              <uri>https://fuel.gazebosim.org/1.0/openrobotics/models/pine tree/6/files/materials/scripts/</uri>
              <uri>https://fuel.gazebosim.org/1.0/openrobotics/models/pine tree/6/files/materials/textures/</uri>
              <name>PineTree/Branch</name>
            </script>
            <pbr>
              <metal>
                <albedo_map>https://fuel.gazebosim.org/1.0/openrobotics/models/pine tree/6/files/materials/textures/branch_2_diffuse.png</albedo_map>
              </metal>
            </pbr>
          </material>
        </visual>
        <visual name='bark'>
          <geometry>
            <mesh>
              <uri>https://fuel.gazebosim.org/1.0/openrobotics/models/pine tree/6/files/meshes/pine_tree.dae</uri>
              <submesh>
                <name>Bark</name>
              </submesh>
            </mesh>
          </geometry>
          <material>
            <diffuse>1 1 1 1</diffuse>
            <script>
              <uri>https://fuel.gazebosim.org/1.0/openrobotics/models/pine tree/6/files/materials/scripts/</uri>
              <uri>https://fuel.gazebosim.org/1.0/openrobotics/models/pine tree/6/files/materials/textures/</uri>
              <name>PineTree/Bark</name>
            </script>
            <pbr>
              <metal>
                <albedo_map>https://fuel.gazebosim.org/1.0/openrobotics/models/pine tree/6/files/materials/textures/bark_diffuse.png</albedo_map>
              </metal>
            </pbr>
          </material>
        </visual>
        <pose>0 0 0 0 0 0</pose>
        <inertial>
          <pose>0 0 0 0 0 0</pose>
          <mass>1</mass>
          <inertia>
            <ixx>1</ixx>
            <ixy>0</ixy>
            <ixz>0</ixz>
            <iyy>1</iyy>
            <iyz>0</iyz>
            <izz>1</izz>
          </inertia>
        </inertial>
        <enable_wind>false</enable_wind>
      </link>
      <pose>-18.164899826049805 -13.663352012634277 0 0 0 0</pose>
      <self_collide>false</self_collide>
    </model>
    <model name='ground_plane'>
      <static>true</static>
      <pose>0 0 -0.050000000000000003 0 0 0</pose>
      <link name='link'>
        <collision name='collision'>
          <geometry>
            <box>
              <size>75 50 0.10000000000000001</size>
            </box>
          </geometry>
          <surface>
            <friction>
              <ode/>
            </friction>
            <bounce/>
            <contact/>
          </surface>
        </collision>
        <visual name='visual'>
          <geometry>
            <box>
              <size>75 50 0.10000000000000001</size>
            </box>
          </geometry>
          <material>
            <ambient>1 1 1 1</ambient>
            <diffuse>1 1 1 1</diffuse>
            <specular>0.100000001 0.100000001 0.100000001 1</specular>
            <pbr>
              <metal>
                <albedo_map>file:///home/allen/workspace/map.png</albedo_map>
              </metal>
            </pbr>
          </material>
        </visual>
        <pose>0 0 0 0 0 0</pose>
        <inertial>
          <pose>0 0 0 0 0 0</pose>
          <mass>1</mass>
          <inertia>
            <ixx>1</ixx>
            <ixy>0</ixy>
            <ixz>0</ixz>
            <iyy>1</iyy>
            <iyz>0</iyz>
            <izz>1</izz>
          </inertia>
        </inertial>
        <enable_wind>false</enable_wind>
      </link>
      <self_collide>false</self_collide>
    </model>
    <model name='ELM4-Chassis'>
      <pose>-2.1516902507618245 17.87512588398673 0.1535109844088054 -4.7257107182422014e-10 2.6271303409868596e-05 5.1692080929117073e-09</pose>
      <self_collide>false</self_collide>
      <static>false</static>
      <link name='ELM4-Chassis/Base'>
        <inertial>
          <mass>18.710000000000001</mass>
          <inertia>
            <ixx>0.39860000000000001</ixx>
            <ixy>0</ixy>
            <ixz>0</ixz>
            <iyy>1.0920000000000001</iyy>
            <iyz>0</iyz>
            <izz>1.337</izz>
          </inertia>
          <pose>0 0 0 0 0 0</pose>
        </inertial>
        <gravity>true</gravity>
        <velocity_decay/>
        <collision name='ELM4-Chassis/Base_Collision'>
          <pose>0 0 0.087499999999999994 0 0 0</pose>
          <geometry>
            <box>
              <size>0.80000000000000004 0.38900000000000001 0.17100000000000001</size>
            </box>
          </geometry>
          <surface>
            <contact>
              <ode>
                <min_depth>0.001</min_depth>
                <max_vel>0</max_vel>
              </ode>
            </contact>
            <friction>
              <ode/>
            </friction>
            <bounce/>
          </surface>
        </collision>
        <visual name='ELM4-Chassis/BaseMetal'>
          <pose>0 0 0 0 0 0</pose>
          <geometry>
            <mesh>
              <scale>1 1 1</scale>
              <uri>file:///home/allen/workspace/meshes/BaseMetal.dae</uri>
            </mesh>
          </geometry>
        </visual>
        <visual name='ELM4-Chassis/BaseRubber'>
          <pose>0 0 0 0 0 0</pose>
          <geometry>
            <mesh>
              <scale>1 1 1</scale>
              <uri>file:///home/allen/workspace/meshes/BaseRubber.dae</uri>
            </mesh>
          </geometry>
        </visual>
        <visual name='ELM4-Chassis/BaseYellowPlasticTop'>
          <pose>0 0 0 0 0 0</pose>
          <geometry>
            <mesh>
              <scale>1 1 1</scale>
              <uri>file:///home/allen/workspace/meshes/BasePlastic.dae</uri>
            </mesh>
          </geometry>
        </visual>
        <visual name='ELM4-Chassis/BaseClearPlasticGuard'>
          <pose>0 0 0 0 0 0</pose>
          <transparency>0.5</transparency>
          <geometry>
            <mesh>
              <scale>1 1 1</scale>
              <uri>file:///home/allen/workspace/meshes/BaseClear.dae</uri>
            </mesh>
          </geometry>
          <material>
            <diffuse>0.600000024 0.600000024 0.699999988 1</diffuse>
            <ambient>0.600000024 0.600000024 0.699999988 1</ambient>
          </material>
        </visual>
        <pose>0 0 0 0 0 0</pose>
        <enable_wind>false</enable_wind>
      </link>
      <link name='ELM4-Chassis/FrontLeftArm'>
        <pose>0.26300000001877089 0.23799999999360821 0.028999584855148752 2.3202484278792097e-10 -0.00024825126291538375 1.3626355026703354e-10</pose>
        <inertial>
          <mass>1.1599999999999999</mass>
          <inertia>
            <ixx>0.0062740000000000001</ixx>
            <ixy>0.0027439999999999999</ixy>
            <ixz>0</ixz>
            <iyy>0.0076779999999999999</iyy>
            <iyz>0</iyz>
            <izz>0.0094079999999999997</izz>
          </inertia>
          <pose>0 0 0 0 0 0</pose>
        </inertial>
        <gravity>true</gravity>
        <velocity_decay/>
        <visual name='ELM4-Chassis/FrontLeftArmMetal_Visual'>
          <pose>0 0 0 0 0 0</pose>
          <geometry>
            <mesh>
              <scale>1 1 1</scale>
              <uri>file:///home/allen/workspace/meshes/ArmLeftMetal.dae</uri>
            </mesh>
          </geometry>
        </visual>
        <visual name='ELM4-Chassis/FrontLeftArmPlastic_Visual'>
          <pose>0 0 0 0 0 0</pose>
          <geometry>
            <mesh>
              <scale>1 1 1</scale>
              <uri>file:///home/allen/workspace/meshes/ArmLeftPlastic.dae</uri>
            </mesh>
          </geometry>
        </visual>
        <collision name='ELM4-Chassis/FrontLeftArm_Collision'>
          <pose>0.055 0 -0.030499999999999999 0 0.505 0</pose>
          <geometry>
            <box>
              <size>0.20999999999999999 0.074999999999999997 0.037999999999999999</size>
            </box>
          </geometry>
          <surface>
            <contact>
              <ode>
                <min_depth>0.001</min_depth>
                <max_vel>0</max_vel>
              </ode>
            </contact>
            <friction>
              <ode/>
            </friction>
            <bounce/>
          </surface>
        </collision>
        <enable_wind>false</enable_wind>
      </link>
      <link name='ELM4-Chassis/FrontLeftHubMotorWheel'>
        <pose>0.381628417117168 0.33300000001649721 -0.045500967746265705 1.7364357429233598e-10 -0.00024709847528227411 9.3717991035754182e-11</pose>
        <inertial>
          <mass>3.8540000000000001</mass>
          <inertia>
            <ixx>0.0090019999999999996</ixx>
            <ixy>0.00060210000000000005</ixy>
            <ixz>0</ixz>
            <iyy>0.013129999999999999</iyy>
            <iyz>0</iyz>
            <izz>0.0090030000000000006</izz>
          </inertia>
          <pose>0 0 0 0 0 0</pose>
        </inertial>
        <gravity>true</gravity>
        <velocity_decay/>
        <visual name='ELM4-Chassis/FrontLeftHubMotorWheelMetal_Visual'>
          <pose>0 0 0 0 0 -3.1415926535895866</pose>
          <geometry>
            <mesh>
              <scale>1 1 1</scale>
              <uri>file:///home/allen/workspace/meshes/HubMotor.dae</uri>
            </mesh>
          </geometry>
        </visual>
        <visual name='ELM4-Chassis/FrontLeftHubMotorWheelRubber_Visual'>
          <pose>0 0 0 0 0 -3.1415926535895866</pose>
          <geometry>
            <mesh>
              <scale>1 1 1</scale>
              <uri>file:///home/allen/workspace/meshes/RubberWheel.dae</uri>
            </mesh>
          </geometry>
        </visual>
        <collision name='ELM4-Chassis/FrontLeftHubMotorWheel_Collision'>
          <pose>0 0 0 1.57079632679 0 0</pose>
          <geometry>
            <cylinder>
              <radius>0.108</radius>
              <length>0.059999999999999998</length>
            </cylinder>
          </geometry>
          <surface>
            <contact>
              <ode>
                <min_depth>0.001</min_depth>
                <max_vel>0</max_vel>
              </ode>
            </contact>
            <friction>
              <ode>
                <mu>1</mu>
                <mu2>0.80000000000000004</mu2>
                <fdir1>1 0 0</fdir1>
              </ode>
            </friction>
            <bounce/>
          </surface>
        </collision>
        <enable_wind>false</enable_wind>
      </link>
      <joint name='ELM4-Chassis/FrontLeftArmJoint' type='revolute'>
        <parent>ELM4-Chassis/Base</parent>
        <child>ELM4-Chassis/FrontLeftArm</child>
        <pose>5.5511151231257827e-17 0 0 0 0 0</pose>
        <axis>
          <xyz>0 1 0</xyz>
          <limit>
            <lower>-0.5</lower>
            <upper>0.5</upper>
            <effort>inf</effort>
            <velocity>inf</velocity>
            <stiffness>100000000</stiffness>
            <dissipation>1</dissipation>
          </limit>
          <dynamics>
            <spring_reference>0</spring_reference>
            <spring_stiffness>300</spring_stiffness>
            <damping>0</damping>
            <friction>0</friction>
          </dynamics>
        </axis>
      </joint>
      <joint name='ELM4-Chassis/FrontLeftHubMotorWheelJoint' type='revolute'>
        <parent>ELM4-Chassis/FrontLeftArm</parent>
        <child>ELM4-Chassis/FrontLeftHubMotorWheel</child>
        <pose>0 5.5511151231257827e-17 0 0 0 0</pose>
        <axis>
          <xyz>0 1 0</xyz>
          <limit>
            <lower>-10000000000000000</lower>
            <upper>10000000000000000</upper>
            <effort>inf</effort>
            <velocity>inf</velocity>
            <stiffness>100000000</stiffness>
            <dissipation>1</dissipation>
          </limit>
          <dynamics>
            <spring_reference>0</spring_reference>
            <spring_stiffness>0</spring_stiffness>
            <damping>0</damping>
            <friction>0</friction>
          </dynamics>
        </axis>
      </joint>
      <link name='ELM4-Chassis/BackLeftArm'>
        <pose>-0.26299999992802015 -0.23800000006895772 0.028999642942592163 -2.0714621787925131e-10 -7.8723571894354761e-05 -3.1415926534723511</pose>
        <inertial>
          <mass>1.1599999999999999</mass>
          <inertia>
            <ixx>0.0062740000000000001</ixx>
            <ixy>0.0027439999999999999</ixy>
            <ixz>0</ixz>
            <iyy>0.0076779999999999999</iyy>
            <iyz>0</iyz>
            <izz>0.0094079999999999997</izz>
          </inertia>
          <pose>0 0 0 0 0 0</pose>
        </inertial>
        <gravity>true</gravity>
        <velocity_decay/>
        <visual name='ELM4-Chassis/BackLeftArmMetal_Visual'>
          <pose>0 0 0 0 0 0</pose>
          <geometry>
            <mesh>
              <scale>1 1 1</scale>
              <uri>file:///home/allen/workspace/meshes/ArmLeftMetal.dae</uri>
            </mesh>
          </geometry>
        </visual>
        <visual name='ELM4-Chassis/BackLeftArmPlastic_Visual'>
          <pose>0 0 0 0 0 0</pose>
          <geometry>
            <mesh>
              <scale>1 1 1</scale>
              <uri>file:///home/allen/workspace/meshes/ArmLeftPlastic.dae</uri>
            </mesh>
          </geometry>
        </visual>
        <collision name='ELM4-Chassis/BackLeftArm_Collision'>
          <pose>0.055 0 -0.030499999999999999 0 0.505 0</pose>
          <geometry>
            <box>
              <size>0.20999999999999999 0.074999999999999997 0.037999999999999999</size>
            </box>
          </geometry>
          <surface>
            <contact>
              <ode>
                <min_depth>0.001</min_depth>
                <max_vel>0</max_vel>
              </ode>
            </contact>
            <friction>
              <ode/>
            </friction>
            <bounce/>
          </surface>
        </collision>
        <enable_wind>false</enable_wind>
      </link>
      <link name='ELM4-Chassis/BackLeftHubMotorWheel'>
        <pose>-0.38161578562553666 -0.33300000004413377 -0.045521019441268948 1.4393120302706963e-10 7.757361318473622e-05 7.5202679537471497e-11</pose>
        <inertial>
          <mass>3.8540000000000001</mass>
          <inertia>
            <ixx>0.0090019999999999996</ixx>
            <ixy>0.00060210000000000005</ixy>
            <ixz>0</ixz>
            <iyy>0.013129999999999999</iyy>
            <iyz>0</iyz>
            <izz>0.0090030000000000006</izz>
          </inertia>
          <pose>0 0 0 0 0 0</pose>
        </inertial>
        <gravity>true</gravity>
        <velocity_decay/>
        <visual name='ELM4-Chassis/BackLeftHubMotorWheelMetal_Visual'>
          <pose>0 0 0 0 0 0</pose>
          <geometry>
            <mesh>
              <scale>1 1 1</scale>
              <uri>file:///home/allen/workspace/meshes/HubMotor.dae</uri>
            </mesh>
          </geometry>
        </visual>
        <visual name='ELM4-Chassis/BackLeftHubMotorWheelRubber_Visual'>
          <pose>0 0 0 0 0 0</pose>
          <geometry>
            <mesh>
              <scale>1 1 1</scale>
              <uri>file:///home/allen/workspace/meshes/RubberWheel.dae</uri>
            </mesh>
          </geometry>
        </visual>
        <collision name='ELM4-Chassis/BackLeftHubMotorWheel_Collision'>
          <pose>0 0 0 1.57079632679 0 0</pose>
          <geometry>
            <cylinder>
              <radius>0.108</radius>
              <length>0.059999999999999998</length>
            </cylinder>
          </geometry>
          <surface>
            <contact>
              <ode>
                <min_depth>0.001</min_depth>
                <max_vel>0</max_vel>
              </ode>
            </contact>
            <friction>
              <ode>
                <mu>1</mu>
                <mu2>0.80000000000000004</mu2>
                <fdir1>1 0 0</fdir1>
              </ode>
            </friction>
            <bounce/>
          </surface>
        </collision>
        <enable_wind>false</enable_wind>
      </link>
      <joint name='ELM4-Chassis/BackLeftArmJoint' type='revolute'>
        <parent>ELM4-Chassis/Base</parent>
        <child>ELM4-Chassis/BackLeftArm</child>
        <pose>-5.5511151231257827e-17 -5.5511151231257827e-17 3.4694469519536142e-18 0 0 0</pose>
        <axis>
          <xyz>0 1 0</xyz>
          <limit>
            <lower>-0.5</lower>
            <upper>0.5</upper>
            <effort>inf</effort>
            <velocity>inf</velocity>
            <stiffness>100000000</stiffness>
            <dissipation>1</dissipation>
          </limit>
          <dynamics>
            <spring_reference>0</spring_reference>
            <spring_stiffness>300</spring_stiffness>
            <damping>0</damping>
            <friction>0</friction>
          </dynamics>
        </axis>
      </joint>
      <joint name='ELM4-Chassis/BackLeftHubMotorWheelJoint' type='revolute'>
        <parent>ELM4-Chassis/BackLeftArm</parent>
        <child>ELM4-Chassis/BackLeftHubMotorWheel</child>
        <pose>-1.6653345369377348e-16 -5.5511151231257827e-17 -6.9388939039072284e-18 0 -5.7645287035657714e-33 0</pose>
        <axis>
          <xyz>0 1 0</xyz>
          <limit>
            <lower>-10000000000000000</lower>
            <upper>10000000000000000</upper>
            <effort>inf</effort>
            <velocity>inf</velocity>
            <stiffness>100000000</stiffness>
            <dissipation>1</dissipation>
          </limit>
          <dynamics>
            <spring_reference>0</spring_reference>
            <spring_stiffness>0</spring_stiffness>
            <damping>0</damping>
            <friction>0</friction>
          </dynamics>
        </axis>
      </joint>
      <link name='ELM4-Chassis/FrontRightArm'>
        <pose>0.26300000008277857 -0.23800000000645838 0.028999589005133913 2.3027211967161954e-10 -0.00024821461323785602 1.3486533691126967e-10</pose>
        <inertial>
          <mass>1.1599999999999999</mass>
          <inertia>
            <ixx>0.0062740000000000001</ixx>
            <ixy>0.0027439999999999999</ixy>
            <ixz>0</ixz>
            <iyy>0.0076779999999999999</iyy>
            <iyz>0</iyz>
            <izz>0.0094079999999999997</izz>
          </inertia>
          <pose>0 0 0 0 0 0</pose>
        </inertial>
        <gravity>true</gravity>
        <velocity_decay/>
        <visual name='ELM4-Chassis/FrontRightArmMetal_Visual'>
          <pose>0 0 0 0 -0.016999999999999994 0</pose>
          <geometry>
            <mesh>
              <scale>1 1 1</scale>
              <uri>file:///home/allen/workspace/meshes/ArmRightMetal.dae</uri>
            </mesh>
          </geometry>
        </visual>
        <visual name='ELM4-Chassis/FrontRightArmPlastic_Visual'>
          <pose>0 0 0 0 -0.016999999999999994 0</pose>
          <geometry>
            <mesh>
              <scale>1 1 1</scale>
              <uri>file:///home/allen/workspace/meshes/ArmRightPlastic.dae</uri>
            </mesh>
          </geometry>
        </visual>
        <collision name='ELM4-Chassis/FrontRightArm_Collision'>
          <pose>0.055 0 -0.030499999999999999 0 0.505 0</pose>
          <geometry>
            <box>
              <size>0.20999999999999999 0.074999999999999997 0.037999999999999999</size>
            </box>
          </geometry>
          <surface>
            <contact>
              <ode>
                <min_depth>0.001</min_depth>
                <max_vel>0</max_vel>
              </ode>
            </contact>
            <friction>
              <ode/>
            </friction>
            <bounce/>
          </surface>
        </collision>
        <enable_wind>false</enable_wind>
      </link>
      <link name='ELM4-Chassis/FrontRightHubMotorWheel'>
        <pose>0.38162841480581378 -0.33299999998371987 -0.045500967988109084 1.7183831812592429e-10 -0.00024706677315330309 9.251952834849187e-11</pose>
        <inertial>
          <mass>3.8540000000000001</mass>
          <inertia>
            <ixx>0.0090019999999999996</ixx>
            <ixy>0.00060210000000000005</ixy>
            <ixz>0</ixz>
            <iyy>0.013129999999999999</iyy>
            <iyz>0</iyz>
            <izz>0.0090030000000000006</izz>
          </inertia>
          <pose>0 0 0 0 0 0</pose>
        </inertial>
        <gravity>true</gravity>
        <velocity_decay/>
        <visual name='ELM4-Chassis/FrontRightHubMotorWheelMetal_Visual'>
          <pose>0 0 0 0 0 0</pose>
          <geometry>
            <mesh>
              <scale>1 1 1</scale>
              <uri>file:///home/allen/workspace/meshes/HubMotor.dae</uri>
            </mesh>
          </geometry>
        </visual>
        <visual name='ELM4-Chassis/FrontRightHubMotorWheelRubber_Visual'>
          <pose>0 0 0 0 0 0</pose>
          <geometry>
            <mesh>
              <scale>1 1 1</scale>
              <uri>file:///home/allen/workspace/meshes/RubberWheel.dae</uri>
            </mesh>
          </geometry>
        </visual>
        <collision name='ELM4-Chassis/FrontRightHubMotorWheel_Collision'>
          <pose>0 0 0 1.57079632679 0 0</pose>
          <geometry>
            <cylinder>
              <radius>0.108</radius>
              <length>0.059999999999999998</length>
            </cylinder>
          </geometry>
          <surface>
            <contact>
              <ode>
                <min_depth>0.001</min_depth>
                <max_vel>0</max_vel>
              </ode>
            </contact>
            <friction>
              <ode>
                <mu>1</mu>
                <mu2>0.80000000000000004</mu2>
                <fdir1>1 0 0</fdir1>
              </ode>
            </friction>
            <bounce/>
          </surface>
        </collision>
        <enable_wind>false</enable_wind>
      </link>
      <joint name='ELM4-Chassis/FrontRightArmJoint' type='revolute'>
        <parent>ELM4-Chassis/Base</parent>
        <child>ELM4-Chassis/FrontRightArm</child>
        <pose>0 0 0 2.0614357324980701e-92 -4.4894094739829878e-52 -9.1835496157991212e-41</pose>
        <axis>
          <xyz>9.1835496157991212e-41 1 2.0614357324980701e-92</xyz>
          <limit>
            <lower>-0.5</lower>
            <upper>0.5</upper>
            <effort>inf</effort>
            <velocity>inf</velocity>
            <stiffness>100000000</stiffness>
            <dissipation>1</dissipation>
          </limit>
          <dynamics>
            <spring_reference>0</spring_reference>
            <spring_stiffness>300</spring_stiffness>
            <damping>0</damping>
            <friction>0</friction>
          </dynamics>
        </axis>
      </joint>
      <joint name='ELM4-Chassis/FrontRightHubMotorWheelJoint' type='revolute'>
        <parent>ELM4-Chassis/FrontRightArm</parent>
        <child>ELM4-Chassis/FrontRightHubMotorWheel</child>
        <pose>0 0 -1.3877787807814457e-17 0 0 0</pose>
        <axis>
          <xyz>0 1 0</xyz>
          <limit>
            <lower>-10000000000000000</lower>
            <upper>10000000000000000</upper>
            <effort>inf</effort>
            <velocity>inf</velocity>
            <stiffness>100000000</stiffness>
            <dissipation>1</dissipation>
          </limit>
          <dynamics>
            <spring_reference>0</spring_reference>
            <spring_stiffness>0</spring_stiffness>
            <damping>0</damping>
            <friction>0</friction>
          </dynamics>
        </axis>
      </joint>
      <link name='ELM4-Chassis/BackRightArm'>
        <pose>-0.26299999998360457 0.23799999993039123 0.028999638903358355 -2.0898454260823625e-10 -7.8760576317825329e-05 -3.1415926534709921</pose>
        <inertial>
          <mass>1.1599999999999999</mass>
          <inertia>
            <ixx>0.0062740000000000001</ixx>
            <ixy>0.0027439999999999999</ixy>
            <ixz>0</ixz>
            <iyy>0.0076779999999999999</iyy>
            <iyz>0</iyz>
            <izz>0.0094079999999999997</izz>
          </inertia>
          <pose>0 0 0 0 0 0</pose>
        </inertial>
        <gravity>true</gravity>
        <velocity_decay/>
        <visual name='ELM4-Chassis/BackRightArmMetal_Visual'>
          <pose>0 0 0 0 -0.016999999999999994 0</pose>
          <geometry>
            <mesh>
              <scale>1 1 1</scale>
              <uri>file:///home/allen/workspace/meshes/ArmRightMetal.dae</uri>
            </mesh>
          </geometry>
        </visual>
        <visual name='ELM4-Chassis/BackRightArmPlastic_Visual'>
          <pose>0 0 0 0 -0.016999999999999994 0</pose>
          <geometry>
            <mesh>
              <scale>1 1 1</scale>
              <uri>file:///home/allen/workspace/meshes/ArmRightPlastic.dae</uri>
            </mesh>
          </geometry>
        </visual>
        <collision name='ELM4-Chassis/BackRightArm_Collision'>
          <pose>0.055 0 -0.030499999999999999 0 0.505 0</pose>
          <geometry>
            <box>
              <size>0.20999999999999999 0.074999999999999997 0.037999999999999999</size>
            </box>
          </geometry>
          <surface>
            <contact>
              <ode>
                <min_depth>0.001</min_depth>
                <max_vel>0</max_vel>
              </ode>
            </contact>
            <friction>
              <ode/>
            </friction>
            <bounce/>
          </surface>
        </collision>
        <enable_wind>false</enable_wind>
      </link>
      <link name='ELM4-Chassis/BackRightHubMotorWheel'>
        <pose>-0.38161578830659293 0.33299999995513474 -0.045521019051411885 1.4601043255344753e-10 7.7609073904365709e-05 7.6481717691694832e-11</pose>
        <inertial>
          <mass>3.8540000000000001</mass>
          <inertia>
            <ixx>0.0090019999999999996</ixx>
            <ixy>0.00060210000000000005</ixy>
            <ixz>0</ixz>
            <iyy>0.013129999999999999</iyy>
            <iyz>0</iyz>
            <izz>0.0090030000000000006</izz>
          </inertia>
          <pose>0 0 0 0 0 0</pose>
        </inertial>
        <gravity>true</gravity>
        <velocity_decay/>
        <visual name='ELM4-Chassis/BackRightHubMotorWheelMetal_Visual'>
          <pose>0 0 0 0 0 -3.1415926535895866</pose>
          <geometry>
            <mesh>
              <scale>1 1 1</scale>
              <uri>file:///home/allen/workspace/meshes/HubMotor.dae</uri>
            </mesh>
          </geometry>
        </visual>
        <visual name='ELM4-Chassis/BackRightHubMotorWheelRubber_Visual'>
          <pose>0 0 0 0 0 -3.1415926535895866</pose>
          <geometry>
            <mesh>
              <scale>1 1 1</scale>
              <uri>file:///home/allen/workspace/meshes/RubberWheel.dae</uri>
            </mesh>
          </geometry>
        </visual>
        <collision name='ELM4-Chassis/BackRightHubMotorWheel_Collision'>
          <pose>0 0 0 1.57079632679 0 0</pose>
          <geometry>
            <cylinder>
              <radius>0.108</radius>
              <length>0.059999999999999998</length>
            </cylinder>
          </geometry>
          <surface>
            <contact>
              <ode>
                <min_depth>0.001</min_depth>
                <max_vel>0</max_vel>
              </ode>
            </contact>
            <friction>
              <ode>
                <mu>1</mu>
                <mu2>0.80000000000000004</mu2>
                <fdir1>1 0 0</fdir1>
              </ode>
            </friction>
            <bounce/>
          </surface>
        </collision>
        <enable_wind>false</enable_wind>
      </link>
      <joint name='ELM4-Chassis/BackRightArmJoint' type='revolute'>
        <parent>ELM4-Chassis/Base</parent>
        <child>ELM4-Chassis/BackRightArm</child>
        <pose>5.5511151231257827e-17 0 3.4694469519536142e-18 0 0 0</pose>
        <axis>
          <xyz>0 1 0</xyz>
          <limit>
            <lower>-0.5</lower>
            <upper>0.5</upper>
            <effort>inf</effort>
            <velocity>inf</velocity>
            <stiffness>100000000</stiffness>
            <dissipation>1</dissipation>
          </limit>
          <dynamics>
            <spring_reference>0</spring_reference>
            <spring_stiffness>300</spring_stiffness>
            <damping>0</damping>
            <friction>0</friction>
          </dynamics>
        </axis>
      </joint>
      <joint name='ELM4-Chassis/BackRightHubMotorWheelJoint' type='revolute'>
        <parent>ELM4-Chassis/BackRightArm</parent>
        <child>ELM4-Chassis/BackRightHubMotorWheel</child>
        <pose>5.5511151231257827e-17 0 6.9388939039072284e-18 0 -5.7605696943219912e-33 0</pose>
        <axis>
          <xyz>0 1 0</xyz>
          <limit>
            <lower>-10000000000000000</lower>
            <upper>10000000000000000</upper>
            <effort>inf</effort>
            <velocity>inf</velocity>
            <stiffness>100000000</stiffness>
            <dissipation>1</dissipation>
          </limit>
          <dynamics>
            <spring_reference>0</spring_reference>
            <spring_stiffness>0</spring_stiffness>
            <damping>0</damping>
            <friction>0</friction>
          </dynamics>
        </axis>
      </joint>
      <link name='ELM4-Chassis/camera_link'>
        <pose>0.32466995716095015 -0.0015201568603444571 0.19814213387511143 0 -1.5295076259609302e-21 0</pose>
        <inertial>
          <mass>0.10000000000000001</mass>
          <inertia>
            <ixx>0.00016699999999999999</ixx>
            <iyy>0.00016699999999999999</iyy>
            <izz>0.00016699999999999999</izz>
            <ixy>0</ixy>
            <ixz>0</ixz>
            <iyz>0</iyz>
          </inertia>
          <pose>0 0 0 0 0 0</pose>
        </inertial>
        <visual name='visual'>
          <geometry>
            <box>
              <size>0.050000000000000003 0.050000000000000003 0.050000000000000003</size>
            </box>
          </geometry>
          <material>
            <ambient>0 0 0 1</ambient>
            <diffuse>0 0 0 1</diffuse>
            <specular>0 0 0 1</specular>
          </material>
        </visual>
        <collision name='collision'>
          <geometry>
            <box>
              <size>0.050000000000000003 0.050000000000000003 0.050000000000000003</size>
            </box>
          </geometry>
          <surface>
            <friction>
              <ode/>
            </friction>
            <bounce/>
            <contact/>
          </surface>
        </collision>
        <sensor name='camera' type='camera'>
          <pose>0 0 0 0 0 0</pose>
          <topic>camera</topic>
          <update_rate>30</update_rate>
          <enable_metrics>false</enable_metrics>
          <camera name='__default__'>
            <pose>0 0 0 0 0 0</pose>
            <horizontal_fov>1.0469999999999999</horizontal_fov>
            <image>
              <width>640</width>
              <height>480</height>
              <format>RGB_INT8</format>
              <anti_aliasing>4</anti_aliasing>
            </image>
            <camera_info_topic>__default__</camera_info_topic>
            <trigger_topic></trigger_topic>
            <triggered>false</triggered>
            <clip>
              <near>0.10000000000000001</near>
              <far>100</far>
            </clip>
            <save enabled='false'>
              <path>__default__</path>
            </save>
            <visibility_mask>4294967295</visibility_mask>
            <noise>
              <type>none</type>
              <mean>0</mean>
              <stddev>0</stddev>
            </noise>
            <distortion>
              <k1>0</k1>
              <k2>0</k2>
              <k3>0</k3>
              <p1>0</p1>
              <p2>0</p2>
              <center>0.5 0.5</center>
            </distortion>
            <lens>
              <type>stereographic</type>
              <scale_to_hfov>true</scale_to_hfov>
              <cutoff_angle>1.5707963267948966</cutoff_angle>
              <env_texture_size>256</env_texture_size>
            </lens>
            <optical_frame_id></optical_frame_id>
          </camera>
        </sensor>
        <enable_wind>false</enable_wind>
      </link>
      <joint name='ELM4-Chassis/camera_joint' type='fixed'>
        <parent>ELM4-Chassis/Base</parent>
        <child>ELM4-Chassis/camera_link</child>
        <pose>0 0 0 0 0 0</pose>
      </joint>
      <plugin name='ignition::gazebo::systems::DiffDrive' filename='libignition-gazebo-diff-drive-system.so'>
        <right_joint>ELM4-Chassis/BackLeftHubMotorWheelJoint</right_joint>
        <left_joint>ELM4-Chassis/FrontLeftHubMotorWheelJoint</left_joint>
        <left_joint>ELM4-Chassis/BackRightHubMotorWheelJoint</left_joint>
        <right_joint>ELM4-Chassis/FrontRightHubMotorWheelJoint</right_joint>
        <wheel_separation>0.667</wheel_separation>
        <wheel_radius>0.108</wheel_radius>
        <topic>cmd_vel</topic>
      </plugin>
    </model>
    <model name='Oak tree_1'>
      <static>true</static>
      <link name='link'>
        <collision name='collision'>
          <geometry>
            <mesh>
              <uri>https://fuel.gazebosim.org/1.0/openrobotics/models/oak tree/7/files/meshes/oak_tree.dae</uri>
            </mesh>
          </geometry>
        </collision>
        <visual name='branch'>
          <geometry>
            <mesh>
              <uri>https://fuel.gazebosim.org/1.0/openrobotics/models/oak tree/7/files/meshes/oak_tree.dae</uri>
              <submesh>
                <name>Branch</name>
              </submesh>
            </mesh>
          </geometry>
          <material>
            <double_sided>true</double_sided>
            <diffuse>1 1 1 1</diffuse>
            <script>
              <uri>https://fuel.gazebosim.org/1.0/openrobotics/models/oak tree/7/files/materials/scripts/</uri>
              <uri>https://fuel.gazebosim.org/1.0/openrobotics/models/oak tree/7/files/materials/textures/</uri>
              <name>OakTree/Branch</name>
            </script>
            <pbr>
              <metal>
                <albedo_map>https://fuel.gazebosim.org/1.0/openrobotics/models/oak tree/7/files/materials/textures/branch_diffuse.png</albedo_map>
              </metal>
            </pbr>
          </material>
        </visual>
        <visual name='bark'>
          <geometry>
            <mesh>
              <uri>https://fuel.gazebosim.org/1.0/openrobotics/models/oak tree/7/files/meshes/oak_tree.dae</uri>
              <submesh>
                <name>Bark</name>
              </submesh>
            </mesh>
          </geometry>
          <material>
            <diffuse>1 1 1 1</diffuse>
            <script>
              <uri>https://fuel.gazebosim.org/1.0/openrobotics/models/oak tree/7/files/materials/scripts/</uri>
              <uri>https://fuel.gazebosim.org/1.0/openrobotics/models/oak tree/7/files/materials/textures/</uri>
              <name>OakTree/Bark</name>
            </script>
            <pbr>
              <metal>
                <albedo_map>https://fuel.gazebosim.org/1.0/openrobotics/models/oak tree/7/files/materials/textures/bark_diffuse.png</albedo_map>
              </metal>
            </pbr>
          </material>
        </visual>
        <pose>0 0 0 0 0 0</pose>
        <inertial>
          <pose>0 0 0 0 0 0</pose>
          <mass>1</mass>
          <inertia>
            <ixx>1</ixx>
            <ixy>0</ixy>
            <ixz>0</ixz>
            <iyy>1</iyy>
            <iyz>0</iyz>
            <izz>1</izz>
          </inertia>
        </inertial>
        <enable_wind>false</enable_wind>
      </link>
      <pose>-14.478810143168912 7.3755816434777461 0 0 0 0</pose>
      <self_collide>false</self_collide>
    </model>
    <model name='Oak tree_2'>
      <static>true</static>
      <link name='link'>
        <collision name='collision'>
          <geometry>
            <mesh>
              <uri>https://fuel.gazebosim.org/1.0/openrobotics/models/oak tree/7/files/meshes/oak_tree.dae</uri>
            </mesh>
          </geometry>
        </collision>
        <visual name='branch'>
          <geometry>
            <mesh>
              <uri>https://fuel.gazebosim.org/1.0/openrobotics/models/oak tree/7/files/meshes/oak_tree.dae</uri>
              <submesh>
                <name>Branch</name>
              </submesh>
            </mesh>
          </geometry>
          <material>
            <double_sided>true</double_sided>
            <diffuse>1 1 1 1</diffuse>
            <script>
              <uri>https://fuel.gazebosim.org/1.0/openrobotics/models/oak tree/7/files/materials/scripts/</uri>
              <uri>https://fuel.gazebosim.org/1.0/openrobotics/models/oak tree/7/files/materials/textures/</uri>
              <name>OakTree/Branch</name>
            </script>
            <pbr>
              <metal>
                <albedo_map>https://fuel.gazebosim.org/1.0/openrobotics/models/oak tree/7/files/materials/textures/branch_diffuse.png</albedo_map>
              </metal>
            </pbr>
          </material>
        </visual>
        <visual name='bark'>
          <geometry>
            <mesh>
              <uri>https://fuel.gazebosim.org/1.0/openrobotics/models/oak tree/7/files/meshes/oak_tree.dae</uri>
              <submesh>
                <name>Bark</name>
              </submesh>
            </mesh>
          </geometry>
          <material>
            <diffuse>1 1 1 1</diffuse>
            <script>
              <uri>https://fuel.gazebosim.org/1.0/openrobotics/models/oak tree/7/files/materials/scripts/</uri>
              <uri>https://fuel.gazebosim.org/1.0/openrobotics/models/oak tree/7/files/materials/textures/</uri>
              <name>OakTree/Bark</name>
            </script>
            <pbr>
              <metal>
                <albedo_map>https://fuel.gazebosim.org/1.0/openrobotics/models/oak tree/7/files/materials/textures/bark_diffuse.png</albedo_map>
              </metal>
            </pbr>
          </material>
        </visual>
        <pose>0 0 0 0 0 0</pose>
        <inertial>
          <pose>0 0 0 0 0 0</pose>
          <mass>1</mass>
          <inertia>
            <ixx>1</ixx>
            <ixy>0</ixy>
            <ixz>0</ixz>
            <iyy>1</iyy>
            <iyz>0</iyz>
            <izz>1</izz>
          </inertia>
        </inertial>
        <enable_wind>false</enable_wind>
      </link>
      <pose>17.689658269939724 2.9994857723352624 0 0 0 0</pose>
      <self_collide>false</self_collide>
    </model>
    <model name='Pine Tree_2'>
      <static>true</static>
      <link name='link'>
        <collision name='collision'>
          <geometry>
            <mesh>
              <uri>https://fuel.gazebosim.org/1.0/openrobotics/models/pine tree/6/files/meshes/pine_tree.dae</uri>
            </mesh>
          </geometry>
        </collision>
        <visual name='branch'>
          <geometry>
            <mesh>
              <uri>https://fuel.gazebosim.org/1.0/openrobotics/models/pine tree/6/files/meshes/pine_tree.dae</uri>
              <submesh>
                <name>Branch</name>
              </submesh>
            </mesh>
          </geometry>
          <material>
            <double_sided>true</double_sided>
            <diffuse>1 1 1 1</diffuse>
            <script>
              <uri>https://fuel.gazebosim.org/1.0/openrobotics/models/pine tree/6/files/materials/scripts/</uri>
              <uri>https://fuel.gazebosim.org/1.0/openrobotics/models/pine tree/6/files/materials/textures/</uri>
              <name>PineTree/Branch</name>
            </script>
            <pbr>
              <metal>
                <albedo_map>https://fuel.gazebosim.org/1.0/openrobotics/models/pine tree/6/files/materials/textures/branch_2_diffuse.png</albedo_map>
              </metal>
            </pbr>
          </material>
        </visual>
        <visual name='bark'>
          <geometry>
            <mesh>
              <uri>https://fuel.gazebosim.org/1.0/openrobotics/models/pine tree/6/files/meshes/pine_tree.dae</uri>
              <submesh>
                <name>Bark</name>
              </submesh>
            </mesh>
          </geometry>
          <material>
            <diffuse>1 1 1 1</diffuse>
            <script>
              <uri>https://fuel.gazebosim.org/1.0/openrobotics/models/pine tree/6/files/materials/scripts/</uri>
              <uri>https://fuel.gazebosim.org/1.0/openrobotics/models/pine tree/6/files/materials/textures/</uri>
              <name>PineTree/Bark</name>
            </script>
            <pbr>
              <metal>
                <albedo_map>https://fuel.gazebosim.org/1.0/openrobotics/models/pine tree/6/files/materials/textures/bark_diffuse.png</albedo_map>
              </metal>
            </pbr>
          </material>
        </visual>
        <pose>0 0 0 0 0 0</pose>
        <inertial>
          <pose>0 0 0 0 0 0</pose>
          <mass>1</mass>
          <inertia>
            <ixx>1</ixx>
            <ixy>0</ixy>
            <ixz>0</ixz>
            <iyy>1</iyy>
            <iyz>0</iyz>
            <izz>1</izz>
          </inertia>
        </inertial>
        <enable_wind>false</enable_wind>
      </link>
      <pose>-11.584239581302828 -11.641624842187174 0 0 0 0</pose>
      <self_collide>false</self_collide>
    </model>
    <model name='Oak tree_2_1'>
      <static>true</static>
      <link name='link'>
        <collision name='collision'>
          <geometry>
            <mesh>
              <uri>https://fuel.gazebosim.org/1.0/openrobotics/models/oak tree/7/files/meshes/oak_tree.dae</uri>
            </mesh>
          </geometry>
        </collision>
        <visual name='branch'>
          <geometry>
            <mesh>
              <uri>https://fuel.gazebosim.org/1.0/openrobotics/models/oak tree/7/files/meshes/oak_tree.dae</uri>
              <submesh>
                <name>Branch</name>
              </submesh>
            </mesh>
          </geometry>
          <material>
            <double_sided>true</double_sided>
            <diffuse>1 1 1 1</diffuse>
            <script>
              <uri>https://fuel.gazebosim.org/1.0/openrobotics/models/oak tree/7/files/materials/scripts/</uri>
              <uri>https://fuel.gazebosim.org/1.0/openrobotics/models/oak tree/7/files/materials/textures/</uri>
              <name>OakTree/Branch</name>
            </script>
            <pbr>
              <metal>
                <albedo_map>https://fuel.gazebosim.org/1.0/openrobotics/models/oak tree/7/files/materials/textures/branch_diffuse.png</albedo_map>
              </metal>
            </pbr>
          </material>
        </visual>
        <visual name='bark'>
          <geometry>
            <mesh>
              <uri>https://fuel.gazebosim.org/1.0/openrobotics/models/oak tree/7/files/meshes/oak_tree.dae</uri>
              <submesh>
                <name>Bark</name>
              </submesh>
            </mesh>
          </geometry>
          <material>
            <diffuse>1 1 1 1</diffuse>
            <script>
              <uri>https://fuel.gazebosim.org/1.0/openrobotics/models/oak tree/7/files/materials/scripts/</uri>
              <uri>https://fuel.gazebosim.org/1.0/openrobotics/models/oak tree/7/files/materials/textures/</uri>
              <name>OakTree/Bark</name>
            </script>
            <pbr>
              <metal>
                <albedo_map>https://fuel.gazebosim.org/1.0/openrobotics/models/oak tree/7/files/materials/textures/bark_diffuse.png</albedo_map>
              </metal>
            </pbr>
          </material>
        </visual>
        <pose>0 0 0 0 0 0</pose>
        <inertial>
          <pose>0 0 0 0 0 0</pose>
          <mass>1</mass>
          <inertia>
            <ixx>1</ixx>
            <ixy>0</ixy>
            <ixz>0</ixz>
            <iyy>1</iyy>
            <iyz>0</iyz>
            <izz>1</izz>
          </inertia>
        </inertial>
        <enable_wind>false</enable_wind>
      </link>
      <pose>5.9324264526367188 8.8609199523925781 0 0 0 0</pose>
      <self_collide>false</self_collide>
    </model>
    <light name='sun' type='directional'>
      <pose>0 0 10 0 0 0</pose>
      <cast_shadows>true</cast_shadows>
      <intensity>1</intensity>
      <direction>-0.5 0.10000000000000001 -0.90000000000000002</direction>
      <diffuse>0.800000012 0.800000012 0.800000012 1</diffuse>
      <specular>0.200000003 0.200000003 0.200000003 1</specular>
      <attenuation>
        <range>1000</range>
        <linear>0.01</linear>
        <constant>0.90000000000000002</constant>
        <quadratic>0.001</quadratic>
      </attenuation>
      <spot>
        <inner_angle>0</inner_angle>
        <outer_angle>0</outer_angle>
        <falloff>0</falloff>
      </spot>
    </light>
  </world>
</sdf>
